Workbook

Sheet journey_data
A1: editor | B1: action | C1: lineOfBusiness | D1: channel | E1: product | F1: domain_sequence | G1: domain | H1: sub_domain_sequence | I1: subdomain | J1: business_flow_sequence | K1: business_flow | L1: e2eux_sequence | M1: sequence_uml | N1: e2eux | O1: correlation_id | P1: application | Q1: api | R1: Date Updated | S1: SOX Control | T1: Column1
A2: bb0063 | B2: Add | C2: Mass Markets | D2: Field | E2: Broadband | F2: 2 | G2: Onboard & Activate | H2: 5 | I2: Setup & Activate | J2: 1 | K2: Install Consumer Broadband | L2: 16 | N2: Check Port | O2: 10417 | P2: =IF(Table14[[#This Row],[correlation_id]] = "", "", _xlfn.XLOOKUP(Table14[[#This Row],[correlation_id]], 'ITAP Ref'!A:A, 'ITAP Ref'!C:C, "")) -> G2 | Q2: verifySAMPolicies
A3: bb0063 | B3: Add | C3: Mass Markets | D3: Field | E3: Broadband | F3: 2 | G3: Onboard & Activate | H3: 5 | I3: Setup & Activate | J3: 1 | K3: Install Consumer Broadband | L3: 16 | N3: Check Port | O3: 10417 | P3: =IF(Table14[[#This Row],[correlation_id]] = "", "", _xlfn.XLOOKUP(Table14[[#This Row],[correlation_id]], 'ITAP Ref'!A:A, 'ITAP Ref'!C:C, "")) -> G2 | Q3: verifyCMSPolicies
A4: bb0063 | B4: Add | C4: Mass Markets | D4: Field | E4: Broadband | F4: 2 | G4: Onboard & Activate | H4: 5 | I4: Setup & Activate | J4: 1 | K4: Install Consumer Broadband | L4: 23 | N4: Activate Customer | O4: 10038 | P4: =IF(Table14[[#This Row],[correlation_id]] = "", "", _xlfn.XLOOKUP(Table14[[#This Row],[correlation_id]], 'ITAP Ref'!A:A, 'ITAP Ref'!C:C, "")) -> LS-OMS | Q4: UpdateProductConfiguration
A5: bb0063 | B5: Add | C5: Mass Markets | D5: Care | E5: Broadband | F5: 4 | G5: Service & Support | H5: 1 | I5: Report Issue | J5: 1 | K5: CallBack ATTGuarantee | L5: 1 | N5: Receive Call | O5: 29243 | P5: =IF(Table14[[#This Row],[correlation_id]] = "", "", _xlfn.XLOOKUP(Table14[[#This Row],[correlation_id]], 'ITAP Ref'!A:A, 'ITAP Ref'!C:C, "")) -> HVD-VDI
A6: bb0063 | B6: Add | C6: Mass Markets | D6: Care | E6: Broadband | F6: 4 | G6: Service & Support | H6: 1 | I6: Report Issue | J6: 1 | K6: CallBack ATTGuarantee | L6: 1 | M6: HVD-VDI ->> HVD-VDI Sonus TCCS ->> Sonus TCCS | N6: Receive Call | O6: 26630 | P6: =IF(Table14[[#This Row],[correlation_id]] = "", "", _xlfn.XLOOKUP(Table14[[#This Row],[correlation_id]], 'ITAP Ref'!A:A, 'ITAP Ref'!C:C, "")) -> Sonus TCCS
A7: bb0063 | B7: Add | C7: Mass Markets | D7: Care | E7: Broadband | F7: 4 | G7: Service & Support | H7: 1 | I7: Report Issue | J7: 1 | K7: CallBack ATTGuarantee | L7: 2 | N7: IVR Menu | O7: 10593 | P7: =IF(Table14[[#This Row],[correlation_id]] = "", "", _xlfn.XLOOKUP(Table14[[#This Row],[correlation_id]], 'ITAP Ref'!A:A, 'ITAP Ref'!C:C, "")) -> ISAAC WFE | Q7: POST /restservices/csicustomercareprofile/v2/adapter | R7: 45939
A8: bb0063 | B8: Add | C8: Mass Markets | D8: Field | E8: Broadband | F8: 2 | G8: Onboard & Activate | H8: 5 | I8: Setup & Activate | J8: 1 | K8: Install Consumer Broadband | L8: 16 | N8: Check Port | O8: 9723 | P8: =IF(Table14[[#This Row],[correlation_id]] = "", "", _xlfn.XLOOKUP(Table14[[#This Row],[correlation_id]], 'ITAP Ref'!A:A, 'ITAP Ref'!C:C, "")) -> GRANITE | Q8: updateFiberJack | R8: 45923
A9: bb0063 | B9: Add | C9: Mass Markets | D9: Field | E9: Broadband | F9: 2 | G9: Onboard & Activate | H9: 5 | I9: Setup & Activate | J9: 1 | K9: Install Consumer Broadband | L9: 4 | N9: Select Job / View Comments | O9: 19062 | P9: =IF(Table14[[#This Row],[correlation_id]] = "", "", _xlfn.XLOOKUP(Table14[[#This Row],[correlation_id]], 'ITAP Ref'!A:A, 'ITAP Ref'!C:C, "")) -> EDGE | Q9: UpdateDispatchWorkOrder
A10: bb0063 | B10: Add | C10: Mass Markets | D10: Field | E10: Broadband | F10: 2 | G10: Onboard & Activate | H10: 5 | I10: Setup & Activate | J10: 1 | K10: Install Consumer Broadband | L10: 6 | N10: Arrive on Prem / Update Job | O10: 19062 | P10: =IF(Table14[[#This Row],[correlation_id]] = "", "", _xlfn.XLOOKUP(Table14[[#This Row],[correlation_id]], 'ITAP Ref'!A:A, 'ITAP Ref'!C:C, "")) -> EDGE | Q10: UpdateDispatchWorkOrder
A11: bb0063 | B11: Add | C11: Mass Markets | D11: Field | E11: Broadband | F11: 2 | G11: Onboard & Activate | H11: 5 | I11: Setup & Activate | J11: 1 | K11: Install Consumer Broadband | L11: 24 | N11: Mark Job Complete | O11: 19062 | P11: =IF(Table14[[#This Row],[correlation_id]] = "", "", _xlfn.XLOOKUP(Table14[[#This Row],[correlation_id]], 'ITAP Ref'!A:A, 'ITAP Ref'!C:C, "")) -> EDGE | Q11: UpdateDispatchWorkOrder
A12: bb0063 | B12: Add | C12: Mass Markets | D12: Field | E12: Broadband | F12: 2 | G12: Onboard & Activate | H12: 5 | I12: Setup & Activate | J12: 1 | K12: Install Consumer Broadband | L12: 7 | N12: Review Order w/Customer | O12: 10038 | P12: =IF(Table14[[#This Row],[correlation_id]] = "", "", _xlfn.XLOOKUP(Table14[[#This Row],[correlation_id]], 'ITAP Ref'!A:A, 'ITAP Ref'!C:C, "")) -> LS-OMS | Q12: submitSignature
A13: bb0063 | B13: Add | C13: Mass Markets | D13: Field | E13: Broadband | F13: 2 | G13: Onboard & Activate | H13: 5 | I13: Setup & Activate | J13: 1 | K13: Install Consumer Broadband | L13: 5 | M13: SHM ->> SHM : shmLoginPushCheck | N13: Contact Customer / Verify ETA | O13: 26965 | P13: =IF(Table14[[#This Row],[correlation_id]] = "", "", _xlfn.XLOOKUP(Table14[[#This Row],[correlation_id]], 'ITAP Ref'!A:A, 'ITAP Ref'!C:C, "")) -> SHM | Q13: shmLoginPushCheck | R13: 45937
A14: bb0063 | B14: Add | C14: Mass Markets | D14: Field | E14: Broadband | F14: 2 | G14: Onboard & Activate | H14: 5 | I14: Setup & Activate | J14: 1 | K14: Install Consumer Broadband | L14: 22 | N14: Register RG | O14: 26965 | P14: =IF(Table14[[#This Row],[correlation_id]] = "", "", _xlfn.XLOOKUP(Table14[[#This Row],[correlation_id]], 'ITAP Ref'!A:A, 'ITAP Ref'!C:C, "")) -> SHM | Q14: shmLoginPushCheck | R14: 45937
A15: bb0063 | B15: Add | C15: Mass Markets | D15: Field | E15: Broadband | F15: 2 | G15: Onboard & Activate | H15: 5 | I15: Setup & Activate | J15: 1 | K15: Install Consumer Broadband | L15: 8 | N15: Qualify to Terminal / Verify Assignments | O15: 18781 | P15: =IF(Table14[[#This Row],[correlation_id]] = "", "", _xlfn.XLOOKUP(Table14[[#This Row],[correlation_id]], 'ITAP Ref'!A:A, 'ITAP Ref'!C:C, "")) -> ABPT | Q15: SetlnstLinkClickedService
A16: bb0063 | B16: Add | C16: Mass Markets | D16: Field | E16: Broadband | F16: 2 | G16: Onboard & Activate | H16: 5 | I16: Setup & Activate | J16: 1 | K16: Install Consumer Broadband | L16: 7 | N16: Review Order w/Customer | O16: 10038 | P16: =IF(Table14[[#This Row],[correlation_id]] = "", "", _xlfn.XLOOKUP(Table14[[#This Row],[correlation_id]], 'ITAP Ref'!A:A, 'ITAP Ref'!C:C, "")) -> LS-OMS | Q16: sendSignatureDetails
A17: bb0063 | B17: Add | C17: Mass Markets | D17: Field | E17: Broadband | F17: 2 | G17: Onboard & Activate | H17: 5 | I17: Setup & Activate | J17: 1 | K17: Install Consumer Broadband | L17: 7 | N17: Review Order w/Customer | O17: 10038 | P17: =IF(Table14[[#This Row],[correlation_id]] = "", "", _xlfn.XLOOKUP(Table14[[#This Row],[correlation_id]], 'ITAP Ref'!A:A, 'ITAP Ref'!C:C, "")) -> LS-OMS | Q17: sendOpticalSignatureDetails
A18: bb0063 | B18: Add | C18: Mass Markets | D18: Field | E18: Broadband | F18: 2 | G18: Onboard & Activate | H18: 5 | I18: Setup & Activate | J18: 1 | K18: Install Consumer Broadband | L18: 7 | N18: Review Order w/Customer | O18: 10038 | P18: =IF(Table14[[#This Row],[correlation_id]] = "", "", _xlfn.XLOOKUP(Table14[[#This Row],[correlation_id]], 'ITAP Ref'!A:A, 'ITAP Ref'!C:C, "")) -> LS-OMS | Q18: saveSignature
A19: tm0828 | B19: Add | C19: Mass Markets | D19: Online | E19: Mobility | F19: 1 | G19: Shop & Purchase | H19: 2 | I19: Order Plan/Device | J19: 1 | K19: Purchase Product | L19: 13 | M19: ATTCOM ->> IDPWebSales: IDPWebSales ->> IDPIDM: IDPWebSales ->> IDPBUPS: updateBillingInformation IDPWebSales ->> TLGMOB: | N19: Enter Billing Information | O19: 33847 | P19: =IF(Table14[[#This Row],[correlation_id]] = "", "", _xlfn.XLOOKUP(Table14[[#This Row],[correlation_id]], 'ITAP Ref'!A:A, 'ITAP Ref'!C:C, "")) -> IDP-BUPS | Q19: updateBillingInformation
A20: bb0063 | B20: Add | C20: Mass Markets | D20: Field | E20: Broadband | F20: 2 | G20: Onboard & Activate | H20: 5 | I20: Setup & Activate | J20: 1 | K20: Install Consumer Broadband | L20: 7 | N20: Review Order w/Customer | O20: 10038 | P20: =IF(Table14[[#This Row],[correlation_id]] = "", "", _xlfn.XLOOKUP(Table14[[#This Row],[correlation_id]], 'ITAP Ref'!A:A, 'ITAP Ref'!C:C, "")) -> LS-OMS | Q20: retrieveSignature
A21: bb0063 | B21: Add | C21: Mass Markets | D21: Field | E21: Broadband | F21: 2 | G21: Onboard & Activate | H21: 5 | I21: Setup & Activate | J21: 1 | K21: Install Consumer Broadband | L21: 16 | N21: Check Port | O21: 10417 | P21: =IF(Table14[[#This Row],[correlation_id]] = "", "", _xlfn.XLOOKUP(Table14[[#This Row],[correlation_id]], 'ITAP Ref'!A:A, 'ITAP Ref'!C:C, "")) -> G2 | Q21: restorePolicyData
A22: bb0063 | B22: Add | C22: Mass Markets | D22: Field | E22: Broadband | F22: 2 | G22: Onboard & Activate | H22: 5 | I22: Setup & Activate | J22: 1 | K22: Install Consumer Broadband | L22: 3 | N22: Review Jobs | O22: 27267 | P22: =IF(Table14[[#This Row],[correlation_id]] = "", "", _xlfn.XLOOKUP(Table14[[#This Row],[correlation_id]], 'ITAP Ref'!A:A, 'ITAP Ref'!C:C, "")) -> (FED) - FASTBPM | Q22: POST /restservices/getLconDetails | R22: 45953
A23: bb0063 | B23: Add | C23: Mass Markets | D23: Field | E23: Broadband | F23: 2 | G23: Onboard & Activate | H23: 5 | I23: Setup & Activate | J23: 1 | K23: Install Consumer Broadband | L23: 4 | N23: Select Job / View Comments | O23: 27267 | P23: =IF(Table14[[#This Row],[correlation_id]] = "", "", _xlfn.XLOOKUP(Table14[[#This Row],[correlation_id]], 'ITAP Ref'!A:A, 'ITAP Ref'!C:C, "")) -> (FED) - FASTBPM | Q23: POST /restservices/getLconDetails | R23: 45953
A24: bb0063 | B24: Add | C24: Mass Markets | D24: Field | E24: Broadband | F24: 2 | G24: Onboard & Activate | H24: 5 | I24: Setup & Activate | J24: 1 | K24: Install Consumer Broadband | L24: 7 | N24: Review Order w/Customer | O24: 27267 | P24: =IF(Table14[[#This Row],[correlation_id]] = "", "", _xlfn.XLOOKUP(Table14[[#This Row],[correlation_id]], 'ITAP Ref'!A:A, 'ITAP Ref'!C:C, "")) -> (FED) - FASTBPM | Q24: POST /restservices/getLconDetails | R24: 45953
A25: bb0063 | B25: Add | C25: Mass Markets | D25: Field | E25: Broadband | F25: 2 | G25: Onboard & Activate | H25: 5 | I25: Setup & Activate | J25: 1 | K25: Install Consumer Broadband | L25: 15 | N25: Select ONT | O25: 14311 | P25: =IF(Table14[[#This Row],[correlation_id]] = "", "", _xlfn.XLOOKUP(Table14[[#This Row],[correlation_id]], 'ITAP Ref'!A:A, 'ITAP Ref'!C:C, "")) -> LSBBT | Q25: ontActivation
A26: bb0063 | B26: Add | C26: Mass Markets | D26: Field | E26: Broadband | F26: 2 | G26: Onboard & Activate | H26: 5 | I26: Setup & Activate | J26: 1 | K26: Install Consumer Broadband | L26: 15 | N26: Select ONT | O26: 14311 | P26: =IF(Table14[[#This Row],[correlation_id]] = "", "", _xlfn.XLOOKUP(Table14[[#This Row],[correlation_id]], 'ITAP Ref'!A:A, 'ITAP Ref'!C:C, "")) -> LSBBT | Q26: integratedOntActivation
A27: bb0063 | B27: Add | C27: Mass Markets | D27: Field | E27: Broadband | F27: 2 | G27: Onboard & Activate | H27: 5 | I27: Setup & Activate | J27: 1 | K27: Install Consumer Broadband | L27: 3 | N27: Review Jobs | O27: 19062 | P27: =IF(Table14[[#This Row],[correlation_id]] = "", "", _xlfn.XLOOKUP(Table14[[#This Row],[correlation_id]], 'ITAP Ref'!A:A, 'ITAP Ref'!C:C, "")) -> EDGE | Q27: InquireDispatchWorkOrderList
A28: bb0063 | B28: Add | C28: Mass Markets | D28: Field | E28: Broadband | F28: 2 | G28: Onboard & Activate | H28: 5 | I28: Setup & Activate | J28: 1 | K28: Install Consumer Broadband | L28: 4 | N28: Select Job / View Comments | O28: 19062 | P28: =IF(Table14[[#This Row],[correlation_id]] = "", "", _xlfn.XLOOKUP(Table14[[#This Row],[correlation_id]], 'ITAP Ref'!A:A, 'ITAP Ref'!C:C, "")) -> EDGE | Q28: InquireDispatchWorkOrderList
A29: bb0063 | B29: Add | C29: Mass Markets | D29: Field | E29: Broadband | F29: 2 | G29: Onboard & Activate | H29: 5 | I29: Setup & Activate | J29: 1 | K29: Install Consumer Broadband | L29: 7 | N29: Review Order w/Customer | O29: 19062 | P29: =IF(Table14[[#This Row],[correlation_id]] = "", "", _xlfn.XLOOKUP(Table14[[#This Row],[correlation_id]], 'ITAP Ref'!A:A, 'ITAP Ref'!C:C, "")) -> EDGE | Q29: InquireDispatchWorkOrderList
A30: bb0063 | B30: Add | C30: Mass Markets | D30: Field | E30: Broadband | F30: 2 | G30: Onboard & Activate | H30: 5 | I30: Setup & Activate | J30: 1 | K30: Install Consumer Broadband | L30: 8 | N30: Qualify to Terminal / Verify Assignments | O30: 18781 | P30: =IF(Table14[[#This Row],[correlation_id]] = "", "", _xlfn.XLOOKUP(Table14[[#This Row],[correlation_id]], 'ITAP Ref'!A:A, 'ITAP Ref'!C:C, "")) -> ABPT | Q30: GetTerminalAppearancesService
A31: bb0063 | B31: Add | C31: Mass Markets | D31: Field | E31: Broadband | F31: 2 | G31: Onboard & Activate | H31: 5 | I31: Setup & Activate | J31: 1 | K31: Install Consumer Broadband | L31: 8 | N31: Qualify to Terminal / Verify Assignments | O31: 18781 | P31: =IF(Table14[[#This Row],[correlation_id]] = "", "", _xlfn.XLOOKUP(Table14[[#This Row],[correlation_id]], 'ITAP Ref'!A:A, 'ITAP Ref'!C:C, "")) -> ABPT | Q31: GetSparePortPairsService
A32: bb0063 | B32: Add | C32: Mass Markets | D32: Field | E32: Broadband | F32: 2 | G32: Onboard & Activate | H32: 5 | I32: Setup & Activate | J32: 1 | K32: Install Consumer Broadband | L32: 12 | N32: Add Port to Door | O32: 18781 | P32: =IF(Table14[[#This Row],[correlation_id]] = "", "", _xlfn.XLOOKUP(Table14[[#This Row],[correlation_id]], 'ITAP Ref'!A:A, 'ITAP Ref'!C:C, "")) -> ABPT | Q32: GetSparePortPairsService
A33: bb0063 | B33: Add | C33: Mass Markets | D33: Field | E33: Broadband | F33: 2 | G33: Onboard & Activate | H33: 5 | I33: Setup & Activate | J33: 1 | K33: Install Consumer Broadband | L33: 8 | N33: Qualify to Terminal / Verify Assignments | O33: 18781 | P33: =IF(Table14[[#This Row],[correlation_id]] = "", "", _xlfn.XLOOKUP(Table14[[#This Row],[correlation_id]], 'ITAP Ref'!A:A, 'ITAP Ref'!C:C, "")) -> ABPT | Q33: GetSparePairsService
A34: bb0063 | B34: Add | C34: Mass Markets | D34: Care | E34: Broadband | F34: 4 | G34: Service & Support | H34: 1 | I34: Report Issue | J34: 1 | K34: CallBack ATTGuarantee | L34: 2 | N34: IVR Menu | O34: 10593 | P34: =IF(Table14[[#This Row],[correlation_id]] = "", "", _xlfn.XLOOKUP(Table14[[#This Row],[correlation_id]], 'ITAP Ref'!A:A, 'ITAP Ref'!C:C, "")) -> ISAAC WFE | Q34: GET /restservices/eco-control/v1/integrations/subscribers/details | R34: 45953
A35: bb0063 | B35: Add | C35: Mass Markets | D35: Care | E35: Broadband | F35: 4 | G35: Service & Support | H35: 1 | I35: Report Issue | J35: 1 | K35: CallBack ATTGuarantee | L35: 2 | N35: IVR Menu | O35: 31468 | P35: =IF(Table14[[#This Row],[correlation_id]] = "", "", _xlfn.XLOOKUP(Table14[[#This Row],[correlation_id]], 'ITAP Ref'!A:A, 'ITAP Ref'!C:C, "")) -> IDP-Cloud-CG
A36: bb0063 | B36: Add | C36: Mass Markets | D36: Field | E36: Broadband | F36: 2 | G36: Onboard & Activate | H36: 5 | I36: Setup & Activate | J36: 1 | K36: Install Consumer Broadband | L36: 12 | N36: Add Port to Door | O36: 18781 | P36: =IF(Table14[[#This Row],[correlation_id]] = "", "", _xlfn.XLOOKUP(Table14[[#This Row],[correlation_id]], 'ITAP Ref'!A:A, 'ITAP Ref'!C:C, "")) -> ABPT | Q36: GetSparePairsService
A37: bb0063 | B37: Add | C37: Mass Markets | D37: Field | E37: Broadband | F37: 2 | G37: Onboard & Activate | H37: 5 | I37: Setup & Activate | J37: 1 | K37: Install Consumer Broadband | L37: 3 | N37: Review Jobs | O37: 27531 | P37: =IF(Table14[[#This Row],[correlation_id]] = "", "", _xlfn.XLOOKUP(Table14[[#This Row],[correlation_id]], 'ITAP Ref'!A:A, 'ITAP Ref'!C:C, "")) -> Digital IDP | Q37: getJobsByUid | R37: 45953
A38: bb0063 | B38: Add | C38: Mass Markets | D38: Field | E38: Broadband | F38: 2 | G38: Onboard & Activate | H38: 5 | I38: Setup & Activate | J38: 1 | K38: Install Consumer Broadband | L38: 8 | N38: Qualify to Terminal / Verify Assignments | O38: 18781 | P38: =IF(Table14[[#This Row],[correlation_id]] = "", "", _xlfn.XLOOKUP(Table14[[#This Row],[correlation_id]], 'ITAP Ref'!A:A, 'ITAP Ref'!C:C, "")) -> ABPT | Q38: GetJobDetailsService
A39: bb0063 | B39: Add | C39: Mass Markets | D39: Field | E39: Broadband | F39: 2 | G39: Onboard & Activate | H39: 5 | I39: Setup & Activate | J39: 1 | K39: Install Consumer Broadband | L39: 9 | N39: Qualify Terminal / True Test | O39: 14311 | P39: =IF(Table14[[#This Row],[correlation_id]] = "", "", _xlfn.XLOOKUP(Table14[[#This Row],[correlation_id]], 'ITAP Ref'!A:A, 'ITAP Ref'!C:C, "")) -> LSBBT | Q39: getFiberTrueTestResults
A40: tm0828 | B40: Add | C40: Mass Markets | D40: Online | E40: Mobility | F40: 1 | G40: Shop & Purchase | H40: 2 | I40: Order Plan/Device | J40: 1 | K40: Purchase Product | L40: 1 | N40: Go to att.com | O40: 31548 | P40: =IF(Table14[[#This Row],[correlation_id]] = "", "", _xlfn.XLOOKUP(Table14[[#This Row],[correlation_id]], 'ITAP Ref'!A:A, 'ITAP Ref'!C:C, "")) -> IDP-Upper Funnel Cloud | Q40: recommendationms
...

Sheet ITAP Ref
A1: Correlation ID | B1: Name | C1: Application acronym | D1: Number | E1: Emergency tier | F1: Business criticality
A2: 100 | B2: Customer Enhanced System for Access Requests | C2: CESAR | D2: APM0008615 | E2: Mission critical | F2: Business Operational | H2: Updated pull 1/8/26
A3: 10010 | B3: Viking Enterprise Account Reconciliation Process (VK EARP) | C3: VK EARP | D3: APM0009082 | E3: Out of Scope | F3: Deferrable
A4: 10013 | B4: Quick Hits HLLAPI Output Generator (HOG) | C4: QH HOG | D4: APM0009083 | E4: Non critical | F4: Administrative
A5: 10027 | B5: TIRKS to Billing Reconciliation | C5: TTBR | D5: APM0009085 | E5: Out of Scope | F5: Administrative
A6: 10035 | B6: Oracle Directory Naming (aka ONames LDAP OUD OID) | C6: ODM | D6: APM0009086 | E6: Out of Scope | F6: Mission Critical
A7: 10038 | B7: Lightspeed Order Management System | C7: LS-OMS | D7: APM0009087 | E7: Mission critical | F7: Mission Critical
A8: 10053 | B8: VMware vCenter | C8: VMVC | D8: APM0009088 | E8: Mission critical | F8: Business Critical
A9: 10055 | B9: Enterprise Bill Message and Insert System | C9: EBMIS | D9: APM0009089 | E9: Non critical | F9: Business Operational
A10: 10056 | B10: Lightspeed CRM | C10: LS CRM | D10: APM0009090 | E10: Mission critical | F10: Mission Critical
A11: 10058 | B11: Got AMA | C11: gotama | D11: APM0009091 | E11: Non critical | F11: Administrative
A12: 10059 | B12: OPT E MAN provision tool | C12: OPT | D12: APM0009092 | E12: Non critical | F12: Administrative
A13: 10089 | B13: Customer Contact System - Tuxedo | C13: CCS-Tuxedo | D13: APM0009060 | E13: Non critical | F13: Business Operational
A14: 10090 | B14: TZSS Business Customized Application Solutions | C14: TZSS BCA | D14: APM0009061 | E14: Out of Scope | F14: Administrative
... A805: 16868 | B805: SN613 & SN613M | C805: SN613 & SN613M | D805: APM0015072 | E805: Non critical | F805: Deferrable
A806: 16874 | B806: Communications Data Group, Inc. Carrier Access Billing System | C806: CDG CABS | D806: APM0009888 | F806: Administrative
A807: 16878 | B807: CISCO-CTM-LNS | C807: CTM-LNS-CISCO | D807: APM0009889 | E807: Non critical | F807: Administrative
A808: 16880 | B808: IP Voice Configuration Manager | C808: IP-VCM | D808: APM0009890 | E808: Non critical | F808: Business Critical
A809: 16883 | B809: NESAC maintenance access and support of 4ESS network elements | C809: NESAC | D809: APM0009891 | E809: Non critical | F809: Deferrable
A810: 16887 | B810: ESCAPE RAM Web Worklist | C810: ESCAPE RAM Web worklist | D810: APM0009892 | E810: Non critical | F810: Administrative
A811: 16890 | B811: IP Solution Center | C811: ISC | D811: APM0009893 | E811: Out of Scope | F811: Administrative
A812: 16891 | B812: Technical Space Operations Intranet | C812: DCSWEB | D812: APM0015886 | E812: Non critical | F812: Deferrable
A813: 16894 | B813: Orbix z/OS(Mainframe) | C813: Orbix z/OS | D813: APM0009872 | E813: Non critical | F813: Business Operational
A814: 16895 | B814: Shared Hosting MQ Infrastructure | C814: SHMQI | D814: APM0009873 | E814: Non critical | F814: Business Critical
A815: 16907 | B815: Layer3 Access servers | C815: OV ASI | D815: APM0009875 | E815: Out of Scope | F815: Administrative
A816: 16909 | B816: ITO DCS Projects | C816: ITODCS | D816: APM0009877 | E816: Out of Scope | F816: Deferrable
A817: 16993 | B817: AFT Discovery | C817: AFT-Discovery | D817: APM0009878 | E817: Non critical | F817: Administrative
A818: 16994 | B818: Converged AT&T Network Operations Provisioning & Inventory | C818: CANOPI | D818: APM0009879 | E818: Mission critical | F818: Business Critical
... A868: 17384 | B868: Cisco CEMF/SCM | C868: Cisco CEMF/SCM | D868: APM0009934 | E868: Out of Scope | F868: Administrative
A869: 17397 | B869: Fraud Tools and Metrics | C869: FraudMetrics | D869: APM0015902 | F869: Deferrable
A870: 17411 | B870: Control-Plane Monitoring | C870: PMOSS_Routing-Mon | D870: APM0014989 | E870: Non critical | F870: Business Operational
A871: 17425 | B871: CSO Website | C871: csowebsite | D871: APM0009936 | E871: Non critical | F871: Deferrable
A872: 17443 | B872: Global TACACS | C872: GTAC | D872: APM0009937 | E872: Mission critical | F872: Business Critical
A873: 17447 | B873: ITO - HP Project and Portfolio Management Center | C873: ITO-HPPPM | D873: APM0009938 | E873: Non critical | F873: Administrative
A874: 17455 | B874: Customer Rules Feedback Tool | C874: CRFT | D874: APM0009939 | E874: Out of Scope | F874: Deferrable
A875: 17456 | B875: Ciena Historical Statistics Collection | C875: Ciena HSC | D875: APM0009940 | F875: Deferrable
A876: 17483 | B876: ETL OPERATIONS | C876: ETL OPS | D876: APM0009943 | E876: Non critical | F876: Administrative
A877: 17484 | B877: E911 External File Server | C877: E911-EFS | D877: APM0009944 | E877: Mission critical | F877: Mission Critical
A878: 17486 | B878: CRE Temp ID | C878: TempID | D878: APM0015477 | E878: Out of Scope | F878: Deferrable
A879: 17488 | B879: CFEngine | C879: CFE | D879: APM0009987 | E879: Non critical | F879: Non-Essential
...

Sheet Pivot
N1: All Applications
A2: application | D2: api | E2: (blank) | N2: EDF
N3: AERO
A4: Row Labels | B4: Count of application | D4: Row Labels | E4: Count of application | N4: EXMGR
A5: Care | B5: 975 | D5: Care | E5: 225 | G5: =(GETPIVOTDATA("application",$A$4,"channel","Care")-GETPIVOTDATA("application",$D$4,"channel","Care"))/GETPIVOTDATA("application",$A$4,"channel","Care") -> 0.76923077 | I5: 0.73026316 | N5: EDGE
A6: Field | B6: 206 | D6: Field | E6: 55 | G6: =(GETPIVOTDATA("application",$A$4,"channel","Field")-GETPIVOTDATA("application",$D$4,"channel","Field"))/GETPIVOTDATA("application",$A$4,"channel","Field") -> 0.73300971 | I6: 0.79550102 | N6: EFMS
A7: Human Resources | B7: 15 | D7: Human Resources | E7: 11 | G7: =(GETPIVOTDATA("application",$A$4,"channel","Human Resources")-GETPIVOTDATA("application",$D$4,"channel","Human Resources"))/GETPIVOTDATA("application",$A$4,"channel","Human Resources") -> 0.26666667 | I7: 0.26666667 | N7: FORCE-DCOE
A8: MVNO | B8: 136 | D8: MVNO | E8: 46 | G8: =(GETPIVOTDATA("application",$A$4,"channel","MVNO")-GETPIVOTDATA("application",$D$4,"channel","MVNO"))/GETPIVOTDATA("application",$A$4,"channel","MVNO") -> 0.66176471 | I8: 0.22068966 | N8: GRETA
A9: Online | B9: 252 | D9: Online | E9: 118 | G9: =(GETPIVOTDATA("application",$A$4,"channel","Online")-GETPIVOTDATA("application",$D$4,"channel","Online"))/GETPIVOTDATA("application",$A$4,"channel","Online") -> 0.53174603 | I9: 0.76190476 | N9: GRID-AC
A10: Retail | B10: 858 | D10: Retail | E10: 98 | G10: =(GETPIVOTDATA("application",$A$4,"channel","Retail")-GETPIVOTDATA("application",$D$4,"channel","Retail"))/GETPIVOTDATA("application",$A$4,"channel","Retail") -> 0.88578089 | I10: 0.83189122 | N10: INSTAR
A11: (blank) | B11: 4 | D11: (blank) | E11: 4 | N11: OCX
A12: Business Field Services | B12: 17 | D12: Business Field Services | E12: 17 | N12: (FED) - OCX
A13: Global Enterprise Sales | B13: 57 | D13: Global Enterprise Sales | E13: 57 | N13: (FED) - OMX
A14: Service Assurance | B14: 55 | D14: Service Assurance | E14: 55 | N14: USRP
A15: Service Delivery | B15: 111 | D15: Service Delivery | E15: 111 | N15: WFA/C
A16: Grand Total | B16: 2686 | D16: Grand Total | E16: 797 | N16: R3:SG
N17: ACMS
N18: SOTS
N19: IDP Web-Support
N20: ATTMO
N21: HVD-VDI
N22: Sonus TCCS
N23: ECO USP
N24: ATT CCT AEP
N25: ATT CCT APIGEE
N26: ATT CCT Service Access Gateway
N27: CCT ATT IPCS
N28: DialogFlow
... N258: ATTCOMM

Sheet Mapping Legend
A1: E2EUX/STATUS Data Model
A2: J-Loader data elements dictionary
A3: Label/Data Element | B3: Description | C3: Notes
A4: editor | B4: Authorized user credentials of individual granted permissions to add/edit/delete
A5: action | B5: Data action: Add, Edit, Delete
A6: lineOfBusiness | B6: Enterprise business unit: Mass Markets, AT&T Business, Corporate Systems
A7: channel | B7: Service delivery function within Line of Business, see Reference Data tab
A8: product | B8: Business unit products aligned to E2EUX, see Reference Data tab
A9: domain_sequence | B9: Numeric value to identify domain order
A10: domain | B10: E2EUX Hiearchy, line of business specific: Lifecycle of the end-to-end customer journey
A11: sub_domain_sequence | B11: Numeric value to identify sub-domain order
A12: subdomain | B12: E2EUX Hiearchy, lifecycle segments within a specific journey domain
A13: business_flow_sequence | B13: Numeric value to identify business flow order | C13: This field will determine the order in which business flows are listed.
A14: business_flow | B14: End to end business process or customer journey
A15: e2eux_sequence | B15: Numeric value to identify E2EUX order | C15: This field will determine the order in which E2EUXes are listed
A16: sequence_uml
A17: e2eux | B17: An E-Tux is the list of repeatable tasks, and their respective technical capabilities used to quantify and measure experience
A18: correlation_id | B18: iTAP application indicator
A19: application | B19: System(s) supporting the E2EUX
A20: api | B20: Application interface(s) enabling systems supporting an E2EUX
A21: Date Updated | B21: Date API data was added to Service Now

Sheet Reference Data
A2: CHANNELS | E2: Mass Markets Journey Model
A3: Corporate Systems | B3: AT&T Business | C3: Mass Markets | E3: MM Channels | F3: MM Products | G3: D Seq | H3: MM Domains | I3: SD Seq | J3: MM Subdomains2
A4: Human Resources | B4: Customer Sales & Support | C4: Field | E4: Field | F4: Mobility | G4: 1 | H4: Shop & Purchase | I4: 1 | J4: Learn & Discover
A5: Finance | B5: Business Field Services | C5: Care | E5: Care | F5: Broadband | I5: 2 | J5: Order Plan/Device
A6: Supply Chain | B6: Customer Advocacy | C6: Retail | E6: Retail | F6: Wholesale Mobility | I6: 3 | J6: Order Addtional Products/Services
B7: Service Assurance | C7: MVNO | E7: MVNO | F7: AIA | I7: 4 | J7: Build Cart
B8: Service Delivery | C8: Online | E8: Online | F8: OneConnect | I8: 5 | J8: Checkout
B9: Global Enterprise Sales | G9: 2 | H9: Onboard & Activate | I9: 1 | J9: Receive Products
B10: Mid-Market Sales | I10: 2 | J10: Unbox Products
B11: Public Sector Sales | I11: 3 | J11: Setup & Activate
B12: Partner Solutions | I12: 4 | J12: Configure Settings & Preferences
B13: International Ecosystem Solutions | G13: 3 | H13: Use & Manage | I13: 1 | J13: Change Settings & Prefrences
B14: Digital Experience | I14: 2 | J14: Change Plan / Change Speed
I15: 3 | J15: Change Feature
A16: PRODUCTS | I16: 4 | J16: Upgrade Device / Equipment
A17: Corporate Systems | B17: Business | C17: Mass Markets | I17: 5 | J17: Order Additional Service
A18: SOX | B18: ABF | C18: Mobility | I18: 6 | J18: Upgrade Roles & Responsibilities
B19: ADI | C19: Wholesale Mobility | G19: 4 | H19: Service & Support | I19: 1 | J19: Report Issue
B20: ASE | C20: Broadband | I20: 2 | J20: Troubleshoot Issue
B21: ASEoD | C21: AIA | I21: 3 | J21: Resolve Issue
B22: IoT with AWB | C22: OneConnect | I22: 4 | J22: Confirm Resolution
B23: Mobility with AWB | I23: 5 | J23: Return Equipment
B24: ADD | G24: 5 | H24: Close & Separate | I24: 1 | J24: Close Account
B25: CRU | I25: 2 | J25: Return Equipment
B26: HSIA
B27: OAH | E27: Business Journey Model
B28: HSIA-E | E28: Business Channels | F28: Business Products | G28: D Seq | H28: Business Domains | I28: SD Seq | J28: Business Subdomains3
E29: Business Care and Sales | F29: ABF | G29: 1 | H29: Learn | I29: 1 | J29: Marketing Managment
A30: DOMAINS | E30: Business Field Services | F30: ADI | I30: 2 | J30: Advertising Management
A31: Corporate Systems | B31: Business | C31: Mass Markets | E31: Customer Advocacy | F31: ASE | I31: 3 | J31: Sales Account Management
A32: Onboard | B32: Learn | C32: Shop & Purchase | E32: Service Assurance | F32: ASEoD | I32: 4 | J32: Sales Activity Management
A33: Manage | B33: Buy | C33: Onboard & Activate | E33: Service Delivery | F33: IoT with AWB | I33: 5 | J33: Campaign Managment
A34: Support | B34: Get | C34: Use & Manage | F34: Mobility with AWB | I34: 6 | J34: Lead Managment
A35: Develop | B35: Use | C35: Service & Support | F35: ADD | I35: 7 | J35: Sales Opportunity Management
A36: Pay | B36: Pay | C36: Close & Separate | E36: Global Enterprise Sales | F36: CRU | I36: 8 | J36: Discovery Management
A37: Separate | B37: Separate | E37: Mid-Market Sales | F37: HSIA | I37: 9 | J37: Qualification Management
A38: Financial Management Approach | E38: Public Sector Sales | F38: OAH | G38: 2 | H38: Buy | I38: 1 | J38: Credit Check Management
A39: Manage Financial Resources | E39: Partner Solutions | F39: HSIA-E | I39: 2 | J39: Contract Management
A40: Manage Treasury | E40: International Ecosystem Solutions | I40: 3 | J40: Sales Order Management
A41: Perform Regulatory & Tax Accounting | I41: 4 | J41: Design Management
...

Sheet Dynatrace Apps
A1: MOTS ID | B1: Application Acronym | C1: Application Name | D1: Dynatrace Monitored
A2: 7983 | B2: #N/A | C2: Email Gateway System | D2: Y
A3: 14798 | C3: Security IDP | D3: Y
A4: 15945 | B4: Email-ODS | C4: Email Operational Data Store | D4: Y
A5: 17689 | B5: EDD | C5: Enterprise Document Delivery | D5: Y
A6: 17723 | B6: myAT&T Sales | C6: myAT&T Sales (MSa) | D6: Y
A7: 17766 | B7: CMS | C7: Content Management System | D7: Y
A8: 18185 | B8: OPSS | C8: Online Post Sales Support | D8: Y
A9: 18298 | B9: MyATT, MSe | C9: myAT&T Services (MSe) | D9: Y
A10: 21937 | B10: #N/A | C10: myAT&T Zone | D10: Y
A11: 23488 | B11: OCE | C11: DET Platform Online Order Capture Engine | D11: Y
A12: 24218 | B12: CMS | C12: Platform Content Management System | D12: Y
A13: 25145 | B13: Dynatrace | C13: DET Platform Dynatrace | D13: Y
A14: 25172 | B14: DET Search | C14: Legacy Search | D14: Y
A15: 26032 | B15: Upper Funnel | C15: Upper Funnel | D15: Y
A16: 27531 | B16: Digital IDP | C16: IDP - Integrated Digital Platform | D16: Y
A17: 27835 | B17: OMHUB | C17: Order Management Hub (Legacy) | D17: Y
A18: 28995 | B18: Order Graph | C18: Order Graph | D18: Y
A19: 29607 | B19: CPOP | C19: Centralized Products and Offers Platform | D19: Y
A20: 30519 | B20: IDP-Sales | C20: IDP-Sales | D20: Y
A21: 30547 | B21: IDP-Srv | C21: IDP-Services | D21: Y
A22: 30635 | B22: IDP-Support | C22: IDP-Support | D22: Y
A23: 30655 | C23: IDP-Platform | D23: Y
A24: 30656 | B24: IDP-Unlock | C24: IDP-Unlock | D24: Y
A25: 30657 | B25: CG | C25: IDP-Customer Graph | D25: Y
A26: 30686 | B26: CCMULE | C26: Customer Connect Salesforce Mulesoft | D26: Y
A27: 31202 | B27: IDP-TOBR | C27: IDP-TOBR | D27: Y
A28: 31467 | B28: IDP-Cloud | C28: IDP-Cloud | D28: Y
A29: 31468 | B29: CGC | C29: IDP-Customer Graph Cloud | D29: Y
A30: 31485 | B30: IDP-Personalization Cloud | C30: IDP-Personalization Cloud | D30: Y
A31: 31501 | B31: IDP- Adobe Personalization Cloud | C31: IDP- Adobe Personalization Cloud | D31: Y
A32: 31543 | B32: OG | C32: IDP-Order Graph Cloud | D32: Y
A33: 31548 | B33: IDP-Upper Funnel Cloud | C33: IDP-Upper Funnel Cloud | D33: Y
A34: 31565 | B34: IDP-PSC | C34: IDP-PSC | D34: Y
A35: 31881 | B35: IDP-Account Services Cloud | C35: IDP-Account Services Cloud | D35: Y
A36: 32166 | B36: IDP-OMHUB | C36: IDP-OMHUB | D36: Y
A37: 32286 | C37: IDP-Event Graph | D37: Y
A38: 32411 | C38: IDP-Sales Cloud | D38: Y
A39: 32470 | C39: IDP-Platform Cloud | D39: Y
A40: 32472 | C40: IDP-Cart Fulfillment Cloud | D40: Y
...

Sheet SvcNow
A1: MotsID | B1: Application | C1: Retail | D1: Care | E1: Field | F1: Online | G1: MVNx | H1: Corp Sys | I1: Ttrace | J1: TAPM | K1: Dynatrace | L1: SvcNow | M1: TAPM Status | N1: T-Trace Status | O1: Penchal Validated | P1: Status
A2: 23223 | B2: (FED) - AOTS | R2: Funded to Retire | S2: 2
A3: 23283 | B3: (FED) - COMS | I3: N | J3: Y | K3: N | M3: Onboarded | O3: Yet to configure in lightStep | P3: TAPM onboarded | R3: Not a candidate (tech stack) | S3: 16
A4: 27267 | B4: (FED) - FASTBPM | E4: X | I4: Y | J4: Y | K4: N | L4: Y | M4: Onboarded | N4: Prod in Progress | O4: configured in lightstep | P4: TAPM onboarded/partial T-Trace | R4: Not a candidate (third party) | S4: 11
A5: 24095 | B5: (FED) - GEARS | G5: X | I5: Y | J5: Y | K5: N | M5: Onboarded | N5: Fully Onboarded | O5: configured in lightstep | P5: TAPM & T-Trace onboarded | R5: Potential/needs review (3Q) | S5: 24
A6: 23439 | B6: (FED) - Interface CAS | C6: X | O6: configured in lightstep | R6: Push back from app team | S6: 2
A7: 23730 | B7: (FED) - TDICE | D7: X | I7: Y | J7: Y | K7: N | L7: Y | M7: Onboarded | N7: Prod in Progress | O7: configured in lightstep | P7: TAPM onboarded/partial T-Trace | R7: Retired | S7: 2
A8: 24433 | B8: (FED) - Unified Services | C8: X | D8: X | O8: configured in lightstep | R8: TAPM & T-Trace onboarded | S8: 15
A9: 23205 | B9: (FED)-CPC | C9: X | D9: X | I9: Y | J9: Y | K9: N | O9: configured in lightstep | R9: TAPM onboarded | S9: 27
A10: 10097 | B10: 5520 AMS | E10: X | I10: N | J10: N | K10: N | L10: N | M10: Potential Candidate | N10: 0 | O10: not available in lightstep | P10: Potential/needs review (3Q) | R10: TAPM Onboarded no traffic | S10: 1
A11: 30176 | B11: AA | D11: X | I11: N | J11: N | K11: N | L11: N | M11: Potential Candidate | N11: 0 | O11: not available in lightstep | P11: Potential/needs review (3Q) | R11: TAPM In Progress/T-Trace Onboarded | S11: 2
A12: 18781 | B12: ABPT | D12: X | E12: X | I12: Y | J12: Y | K12: N | L12: Y | M12: Onboarded | N12: 0 | O12: configured in lightstep | P12: TAPM onboarded | R12: TAPM onboarded / out of scope for T-Trace | S12: 1
A13: 32007 | B13: ABWS-D | E13: X | I13: Y | J13: Y | K13: N | L13: Y | M13: Onboarded | N13: 0 | O13: configured in lightstep | P13: TAPM onboarded | R13: TAPM onboarded/partial T-Trace | S13: 15
A14: 22827 | B14: Amp-MM - Invenio | D14: X | I14: N | J14: Y | K14: N | L14: N | M14: In Progress | N14: 0 | O14: not available in lightstep | P14: Potential/needs review (3Q) | R14: T-Stack Advanced (Dynatrace) | S14: 29
A15: 30420 | B15: Analytics Microservice | R15: T-Trace onboarded | S15: 8
A16: 28619 | B16: Atlas-UI | E16: X | I16: Y | J16: Y | K16: N | L16: Y | M16: Onboarded | N16: Fully Onboarded | O16: configured in lightstep | P16: TAPM & T-Trace onboarded | R16: Total | S16: =SUM(S2:S15) -> 155
A17: 26150 | B17: ATT CCT AEP | D17: X | I17: N | J17: N | K17: N | L17: N | M17: Not a candidate | N17: 0 | P17: Not a candidate (tech stack) | R17: Eligible | S17: 0.8
A18: 30793 | B18: ATT CCT APIGEE | D18: X | I18: N | J18: N | K18: N | L18: N | M18: Not a candidate | N18: 0 | P18: Not a candidate (Third party)
A19: 26215 | B19: ATT CCT Service Access Gateway | D19: X | I19: N | J19: N | K19: N | L19: N | M19: Potential Candidate | N19: 0 | O19: not available in lightstep | P19: Potential/needs review (3Q)
A20: 9367 | B20: ATT CCTP CTI FRAME | D20: X | I20: N | J20: N | K20: N | L20: N | M20: Blocked | N20: 0 | O20: not available in lightstep | P20: Push back from app team
A21: 20813 | B21: ATT CCTP ICM GEN ADAPTER FRAME | D21: X | I21: N | J21: Y | K21: N | L21: N | M21: UAT Complete | N21: 0 | P21: Not a candidate (Third party)
A22: 21359 | B22: ATT CCTP NMC VHT FRAME | D22: X | I22: N | J22: N | K22: N | L22: N | M22: Not a candidate | N22: 0 | P22: Not a candidate (Third party)
A23: 26959 | B23: ATT Coral Desktop | D23: X | I23: N | J23: Y | K23: N | L23: N | M23: In Progress | N23: 0 | O23: not available in lightstep | P23: Potential/needs review (3Q)
A24: 9248 | B24: ATT VERINT CQM | D24: X | I24: N | J24: N | K24: N | L24: N | M24: Not a candidate | N24: 0 | P24: Not a candidate (Third party)
A25: 25114 | B25: Avertack | C25: X | D25: X | I25: N | J25: Y | K25: N | L25: N | M25: In Progress | N25: Blocked | O25: configured in lightstep | P25: Push back from app team
A26: 19105 | B26: AVT | F26: X | I26: Y | J26: Y | K26: N | M26: Onboarded | N26: Fully Onboarded | O26: configured in lightstep | P26: TAPM & T-Trace onboarded
A27: 17215 | B27: BBNMS-CMI | E27: X | I27: N | J27: N | K27: N | L27: N | M27: Not a candidate | N27: 0 | P27: Not a candidate (tech stack)
A28: 16188 | B28: BBNMS-LS | E28: X | I28: Y | J28: N | K28: N | L28: Y | M28: Not a candidate | N28: Fully Onboarded | O28: configured in lightstep | P28: T-Trace onboarded
A29: 18372 | B29: BBNMS-SE | E29: X | I29: N | J29: N | K29: N | L29: N | M29: Not a candidate | N29: 0 | P29: Not a candidate (tech stack)
A30: 30687 | B30: BWSFMC | D30: X | I30: N | J30: N | K30: N | L30: N | M30: Not a candidate | N30: Potential Candidate | P30: Not a candidate (Third party)
A31: 71 | B31: CAMS | E31: X | I31: N | J31: N | K31: N | L31: N | M31: Potential Candidate | N31: 0 | O31: not available in lightstep | P31: Potential/needs review (3Q)
A32: 19867 | B32: CAP | F32: X | I32: N | J32: Y | K32: N | M32: Onboarded | N32: Blocked | O32: Yet to configure in lightStep | P32: TAPM onboarded
A33: 73 | B33: CAPM | C33: X | D33: X | I33: Y | J33: Y | K33: N | L33: Y | M33: Onboarded | N33: Fully Onboarded | O33: configured in lightstep | P33: TAPM & T-Trace onboarded
A34: 18224 | B34: CAS | C34: X | D34: X | I34: Y | J34: Y | K34: N | L34: Y | M34: Onboarded | N34: Prod in Progress | O34: configured in lightstep | P34: TAPM onboarded/partial T-Trace
A35: 33435 | B35: CAST | D35: X | I35: N | J35: N | K35: N | L35: N | M35: Potential Candidate | N35: 0 | O35: not available in lightstep | P35: Potential/needs review (3Q)
A36: 32255 | B36: CCDL | D36: X | I36: N | J36: N | K36: N | L36: N | M36: Potential Candidate | N36: 0 | O36: not available in lightstep | P36: Potential/needs review (3Q)
A37: 18293 | B37: CCM, Clarify, CM | D37: X | I37: N | J37: Y | K37: N | L37: N | M37: Onboarded | N37: 0 | O37: configured in lightstep | P37: TAPM onboarded
A38: 8841 | B38: MPSYS | C38: X | D38: X | F38: X | I38: Y | J38: Y | K38: Y | L38: Y | M38: Onboarded | N38: Fully Onboarded | O38: configured in lightstep | P38: TAPM & T-Trace onboarded
A39: 10038 | B39: LS-OMS | D39: X | E39: X | I39: N | J39: N | K39: Y | L39: N | M39: Not a candidate | N39: Blocked | P39: T-Stack Advanced (Dynatrace)
A40: 33687 | B40: CCMule-Sales | I40: N | J40: N | K40: N | M40: Not a candidate | P40: Not a candidate (tech stack)
...

Sheet App & API Tracking
A1: business_flow | B1: e2eux | C1: correlation_id | D1: application | E1: API Gap | F1: EASE resource | M1: Unique Applications
A2: Consumer Broadband Install | B2: Install Buried Drop Request | C2: 27267 | D2: (FED) - FASTBPM | M2: (FED) - FASTBPM
A3: Activation & Provisioning | B3: Market & Service Area Validation | C3: 24095 | D3: (FED) - GEARS | M3: (FED) - GEARS
A4: Activation & Provisioning | B4: Activate | C4: 24095 | D4: (FED) - GEARS | M4: (FED) - TDICE
A5: TechFast | B5: Agent Troubleshoot | C5: 23730 | D5: (FED) - TDICE | M5: 5520 AMS
A6: Provision/Activation | B6: Test Light @ PFP | C6: 10097 | D6: 5520 AMS | M6: AA
A7: Provision/Activation | B7: Connect ONT | C7: 10097 | D7: 5520 AMS | M7: ABPT
A8: Provision/Activation | B8: Verify Correct ONT for Activation | C8: 10097 | D8: 5520 AMS | M8: Amp-MM - Invenio
A9: Billing Inquiry | B9: Notes Auto Summarization | C9: 30176 | D9: AA | M9: Atlas-UI
A10: Add A Line | B10: Notes Auto Summarization | C10: 30176 | D10: AA | M10: ATT CCT AEP
A11: New Customer | B11: Notes Auto Summarization | C11: 30176 | D11: AA | M11: ATT CCT APIGEE
A12: Activation | B12: Notes Auto Summarization | C12: 30176 | D12: AA | M12: ATT CCT Service Access Gateway
A13: Consumer Broadband Install | B13: Qualify to Terminal/Verify Assignments | C13: 18781 | D13: ABPT | M13: ATT Coral Desktop
... A18: TechFast | B18: Agent Troubleshoot | C18: 22827 | D18: Amp-MM - Invenio | M18: BBNMS-SE
A19: Consumer Broadband Install | B19: Review Jobs | C19: 28619 | D19: Atlas-UI | E19: POG app - no API call | M19: BWSFMC
A20: Consumer Broadband Install | B20: Select Job/View Comments | C20: 28619 | D20: Atlas-UI | E20: POG app - no API call | M20: CAP
A21: Consumer Broadband Install | B21: Arrive on Prem/Update Job | C21: 28619 | D21: Atlas-UI | E21: POG app - no API call | M21: CAPM
A22: Consumer Broadband Install | B22: Review Order w/Customer | C22: 28619 | D22: Atlas-UI | E22: POG app - no API call | M22: CAS
A23: Consumer Broadband Install | B23: Qualify to Terminal/Verify Assignments | C23: 28619 | D23: Atlas-UI | E23: POG app - no API call | M23: CAST
A24: Consumer Broadband Install | B24: True Test/Qualify Terminal | C24: 28619 | D24: Atlas-UI | E24: POG app - no API call | M24: CCDL
A25: Consumer Broadband Install | B25: Place Fiber Connectors | C25: 28619 | D25: Atlas-UI | E25: POG app - no API call | M25: CCM, Clarify, CM
A26: Consumer Broadband Install | B26: Add Port to Door | C26: 28619 | D26: Atlas-UI | E26: POG app - no API call | M26: CCMULE
A27: Consumer Broadband Install | B27: Install Fiber Jack | C27: 28619 | D27: Atlas-UI | E27: POG app - no API call | M27: CCMule-CLM
A28: Consumer Broadband Install | B28: Test Light Levels | C28: 28619 | D28: Atlas-UI | E28: POG app - no API call | M28: CCMule-Service
A29: Consumer Broadband Install | B29: Select ONT | C29: 28619 | D29: Atlas-UI | E29: POG app - no API call | M29: CCR-Relational - CCR-R
A30: Consumer Broadband Install | B30: Check Port | C30: 28619 | D30: Atlas-UI | E30: POG app - no API call | M30: CCSF
... A48: Provision/Activation | B48: Mark Job Complete | C48: 28619 | D48: Atlas-UI | E48: POG app - no API call | M48: DTV-ASMM
A49: TechFast | B49: Log Into Device | C49: 28619 | D49: Atlas-UI | M49: eCDW
A50: TechFast | B50: View Job (Technician) | C50: 28619 | D50: Atlas-UI | E50: POG app - no API call | M50: eCDW Ver - TDATA
A51: Troubleshoot /Repair | B51: Review Jobs | C51: 28619 | D51: Atlas-UI | E51: POG app - no API call | M51: ECM P8
A52: Troubleshoot /Repair | B52: Select Job/View Comments | C52: 28619 | D52: Atlas-UI | E52: POG app - no API call | M52: ECO Suite
A53: Troubleshoot /Repair | B53: Arrive on Prem/Update Job | C53: 28619 | D53: Atlas-UI | E53: POG app - no API call | M53: ECO USP
A54: Troubleshoot /Repair | B54: Review Order w/Customer | C54: 28619 | D54: Atlas-UI | E54: POG app - no API call | M54: ECRMI
A55: Troubleshoot /Repair | B55: Isolate & Resolve | C55: 28619 | D55: Atlas-UI | E55: POG app - no API call | M55: EDGE
A56: Troubleshoot /Repair | B56: Create & Submit Damage Claim | C56: 28619 | D56: Atlas-UI | E56: POG app - no API call | M56: Enabler - C
A57: Troubleshoot /Repair | B57: Submit Bury Request | C57: 28619 | D57: Atlas-UI | E57: POG app - no API call | M57: Enabler LS
A58: Troubleshoot /Repair | B58: Quality Check/True Test | C58: 28619 | D58: Atlas-UI | E58: POG app - no API call | M58: ERBI
A59: Troubleshoot /Repair | B59: Close Job | C59: 28619 | D59: Atlas-UI | E59: POG app - no API call | M59: eTRACS
A60: Provision/Disconnect | B60: Review Job | C60: 28619 | D60: Atlas-UI | E60: POG app - no API call | M60: EXFOWorx
A61: Provision/Disconnect | B61: Select Job/View Comments | C61: 28619 | D61: Atlas-UI | E61: POG app - no API call | M61: FORCE-DCOE
...

Sheet Detail1
A1: Details for Count of application - channel: Online, api: (blank)
A3: editor | B3: action | C3: lineOfBusiness | D3: channel | E3: product | F3: domain_sequence | G3: domain | H3: sub_domain_sequence | I3: subdomain | J3: business_flow_sequence | K3: business_flow | L3: e2eux_sequence | M3: sequence_uml | N3: e2eux | O3: correlation_id | P3: application | Q3: api
A4: tm0828 | B4: Add | C4: Mass Markets | D4: Online | E4: Mobility | F4: 1 | G4: Shop & Purchase | H4: 5 | I4: Checkout | J4: 1 | K4: Purchase Product | L4: 13 | M4: IDP-Web-Sales ->> IDP-IDM : API IDP-Web-Sales ->> TLG-MOB : API IDP-Web-Sales ->> IDP BUPS : updateBillingInformation | N4: Enter Billing Information | O4: 18193 | P4: TLG-MOB
A5: tm0828 | B5: Add | C5: Mass Markets | D5: Online | E5: Mobility | F5: 1 | G5: Shop & Purchase | H5: 1 | I5: Learn & Discover | J5: 3 | K5: Apply Promotions | L5: 1 | M5: TLG-MOB ->> notifyNow : API | N5: Send Promotional Offer to Customer | O5: 18193 | P5: TLG-MOB
A6: tm0828 | B6: Add | C6: Mass Markets | D6: Online | E6: Mobility | F6: 1 | G6: Shop & Purchase | H6: 1 | I6: Learn & Discover | J6: 3 | K6: Apply Promotions | L6: 1 | M6: TLG-MOB ->> notifyNow : API | N6: Send Promotional Offer to Customer | O6: 30920 | P6: notifyNow
A7: tm0828 | B7: Add | C7: Mass Markets | D7: Online | E7: Mobility | F7: 1 | G7: Shop & Purchase | H7: 5 | I7: Checkout | J7: 4 | K7: Upgrade Device | L7: 9 | M7: IDP-Web-Sales ->> IDP-Commerce-Cart&Pricing : api_name_here IDP-Web-Sales ->> IDP-WebAcctMgmt : api_name_here IDP-Commerce-Cart&Pricing ->> IDP-Cart-and-Checkout-UI : api_name_here | N7: Checkout | O7: 33758 | P7: IDP-Web-Sales
A8: tm0828 | B8: Add | C8: Mass Markets | D8: Online | E8: Mobility | F8: 1 | G8: Shop & Purchase | H8: 5 | I8: Checkout | J8: 1 | K8: Purchase Product | L8: 13 | M8: IDP-Web-Sales ->> IDP-IDM : API IDP-Web-Sales ->> TLG-MOB : API IDP-Web-Sales ->> IDP BUPS : updateBillingInformation | N8: Enter Billing Information | O8: 33758 | P8: IDP-Web-Sales
A9: tm0828 | B9: Add | C9: Mass Markets | D9: Online | E9: Mobility | F9: 1 | G9: Shop & Purchase | H9: 5 | I9: Checkout | J9: 1 | K9: Purchase Product | L9: 12 | M9: IDP-Web-Sales ->> IDP-Commerce-Cart&Pricing : api_name_here IDP-Web-Sales ->> IDP-WebAcctMgmt : api_name_here IDP-Commerce-Cart&Pricing ->> IDP-Cart-and-Checkout-UI : api_name_here | N9: Checkout | O9: 33758 | P9: IDP-Web-Sales
A10: tm0828 | B10: Add | C10: Mass Markets | D10: Online | E10: Mobility | F10: 1 | G10: Shop & Purchase | H10: 1 | I10: Learn & Discover | J10: 1 | K10: Purchase Product | L10: 2 | M10: UI ->> IDP Upper Funnel Cloud : CPOP Offers MS IDP Upper Funnel Cloud ->> PLP : online-sales-orchestration IDP Upper Funnel Cloud ->> IDP Web Sales : API | N10: Select "Wireless" | O10: 33758 | P10: IDP-Web-Sales
A11: tm0828 | B11: Add | C11: Mass Markets | D11: Online | E11: Mobility | F11: 3 | G11: Use & Manage | H11: 2 | I11: Change Plan / Change Speed | J11: 2 | K11: Manage Account | L11: 16 | M11: IDP Upper Funnel Cloud ->> IDP WebAcctMgmt : /msapi/wirelessplanmgmt/v1/compare IDP Upper Funnel Cloud ->> IDP Web Sales : API IDP Upper Funnel Cloud ->> IDP-Commerce-Cart&Pricing : API | N11: Compare and Select Wireless Plan | O11: 33758 | P11: IDP-Web-Sales
A12: tm0828 | B12: Add | C12: Mass Markets | D12: Online | E12: Mobility | F12: 1 | G12: Shop & Purchase | H12: 5 | I12: Checkout | J12: 4 | K12: Upgrade Device | L12: 9 | M12: IDP-Web-Sales ->> IDP-Commerce-Cart&Pricing : api_name_here IDP-Web-Sales ->> IDP-WebAcctMgmt : api_name_here IDP-Commerce-Cart&Pricing ->> IDP-Cart-and-Checkout-UI : api_name_here | N12: Checkout | O12: 32768 | P12: IDP-WebAcctMgmt
A13: tm0828 | B13: Add | C13: Mass Markets | D13: Online | E13: Mobility | F13: 1 | G13: Shop & Purchase | H13: 5 | I13: Checkout | J13: 1 | K13: Purchase Product | L13: 12 | M13: IDP-Web-Sales ->> IDP-Commerce-Cart&Pricing : api_name_here IDP-Web-Sales ->> IDP-WebAcctMgmt : api_name_here IDP-Commerce-Cart&Pricing ->> IDP-Cart-and-Checkout-UI : api_name_here | N13: Checkout | O13: 32768 | P13: IDP-WebAcctMgmt
A14: tm0828 | B14: Add | C14: Mass Markets | D14: Online | E14: Mobility | F14: 1 | G14: Shop & Purchase | H14: 5 | I14: Checkout | J14: 3 | K14: Apply Promotions | L14: 8 | M14: IDP-Web-Sales ->> IDP-Commerce-Cart&Pricing : API IDP-Web-Sales ->> IDP-WebAcctMgmt : API IDP-Commerce-Cart&Pricing ->> IDP-Cart-and-Checkout-UI : API | N14: Checkout | O14: 32768 | P14: IDP-WebAcctMgmt
A15: tm0828 | B15: Add | C15: Mass Markets | D15: Online | E15: Mobility | F15: 2 | G15: Onboard & Activate | H15: 1 | I15: Receive Products | J15: 4 | K15: Upgrade Device | L15: 10 | M15: UI ->> IDP Upper Funnel Cloud : API IDP Upper Funnel Cloud ->> IDP Web Sales : Send Purchase Confirmation IDP Web Sales ->> OCE : Order Submitted OCE ->> YODA : Order Information for Fulfillment | N15: Schedule Device Delivery / Pickup | O15: 31548 | P15: IDP-Upper Funnel Cloud
... A63: tm0828 | B63: Add | C63: Mass Markets | D63: Online | E63: Mobility | F63: 4 | G63: Service & Support | H63: 3 | I63: Resolve Issue | J63: 6 | K63: Get Technical Support | L63: 5 | M63: UI ->> IDP Upper Funnel Cloud : API IDP Upper Funnel Cloud ->> IDP Web Support : /msapi/idp-content-orchestration/v1/scms/support/web-support/robocalldetails IDP Upper Funnel Cloud ->> IDP Web Support : /msapi/idp-content-orchestration/v1/scms/support/pages/report-call-or-text IDP Web Support ->> Chat : API IDP Upper Funnel Cloud ->> Chat : API Chat ->> GRID-AC : API Chat ->> AVT : API | N63: Get Live Support | O63: 19105 | P63: AVT

Sheet Sheet1
